Workbook

Sheet Balance Sheet
C1: Q1 2024 | D1: % | E1: Q2 2024 | F1: % | G1: Q3 2024 | H1: % | I1: Q4 2024 | J1: % | K1: Q1 2025 | L1: % | M1: Q2 2025
A2: Assets
B3: Investments in leases - sales-type, net | C3: 22985837 | D3: =(E3-C3)/C3*100 -> 0.88632404 | E3: 23189566 | F3: =(G3-E3)/E3*100 -> 1.0356641 | G3: 23429732 | H3: =(I3-G3)/G3*100 -> 0.64605519 | I3: 23581101 | J3: =(K3-I3)/I3*100 -> -0.3156214 | K3: 23506674 | L3: =(M3-K3)/K3*100 -> 0.76681201 | M3: 23686926
B4: Investments in leases - financing receivables, net | C4: 18266712 | D4: =(E4-C4)/C4*100 -> 0.38961035 | E4: 18337881 | F4: =(G4-E4)/E4*100 -> 0.39385139 | G4: 18410105 | H4: =(I4-G4)/G4*100 -> 0.10980383 | I4: 18430320 | J4: =(K4-I4)/I4*100 -> 0.13400201 | K4: 18455017 | L4: =(M4-K4)/K4*100 -> 0.66413919 | M4: 18577584
B5: Investments in loans and securities, net | C5: 1224987 | D5: =(E5-C5)/C5*100 -> 19.282735 | E5: 1461198 | F5: =(G5-E5)/E5*100 -> 6.1238792 | G5: 1550680 | H5: =(I5-G5)/G5*100 -> 6.5037919 | I5: 1651533 | J5: =(K5-I5)/I5*100 -> 23.311675 | K5: 2036533 | L5: =(M5-K5)/K5*100 -> 16.327553 | M5: 2369049
B6: Land | C6: 150727 | D6: =(E6-C6)/C6*100 -> 0 | E6: 150727 | F6: =(G6-E6)/E6*100 -> 0 | G6: 150727 | H6: =(I6-G6)/G6*100 -> 0 | I6: 150727 | J6: =(K6-I6)/I6*100 -> 0 | K6: 150727 | L6: =(M6-K6)/K6*100 -> -0.62364407 | M6: 149787
B7: Total Assets | C7: 44157873 | D7: =(E7-C7)/C7*100 -> 0.8002582 | E7: 44511250 | F7: =(G7-E7)/E7*100 -> 0.91405207 | G7: 44918106 | H7: =(I7-G7)/G7*100 -> 1.0036799 | I7: 45368940 | J7: =(K7-I7)/I7*100 -> 0.34632504 | K7: 45526064 | L7: =(M7-K7)/K7*100 -> 0.96955669 | M7: 45967465
A9: Liabilities
B10: Debt | C10: 16711739 | D10: =(E10-C10)/C10*100 -> 0.0934792 | E10: 16727361 | F10: =(G10-E10)/E10*100 -> 0.096984814 | G10: 16743584 | H10: =(I10-G10)/G10*100 -> -0.063875213 | I10: 16732889 | J10: =(K10-I10)/I10*100 -> 0.68196233 | K10: 16847001 | L10: =(M10-K10)/K10*100 -> 0.44679762 | M10: 16922273
B11: Accrued expenses and deferred revenue | C11: 186556 | D11: =(E11-C11)/C11*100 -> 15.616222 | E11: 215689 | F11: =(G11-E11)/E11*100 -> -9.9624923 | G11: 194201 | H11: =(I11-G11)/G11*100 -> 12.232172 | I11: 217956 | J11: =(K11-I11)/I11*100 -> -12.116207 | K11: 191548 | L11: =(M11-K11)/K11*100 -> 14.756615 | M11: 219814
B12: Dividends and distributions payable | C12: 437766 | D12: =(E12-C12)/C12*100 -> 0.0043402183 | E12: 437785 | F12: =(G12-E12)/E12*100 -> 4.6123097 | G12: 457977 | H12: =(I12-G12)/G12*100 -> 0.86838422 | I12: 461954 | J12: =(K12-I12)/I12*100 -> 0.029873104 | K12: 462092 | L12: =(M12-K12)/K12*100 -> 0.0045445496 | M12: 462113
B13: Other liabilities | C13: 1003254 | D13: =(E13-C13)/C13*100 -> 0.084524956 | E13: 1004102 | F13: =(G13-E13)/E13*100 -> -0.48102683 | G13: 999272 | H13: =(I13-G13)/G13*100 -> 0.50716922 | I13: 1004340 | J13: =(K13-I13)/I13*100 -> -0.15751638 | K13: 1002758 | L13: =(M13-K13)/K13*100 -> 0.2944878 | M13: 1005711
B14: Total liabilities | C14: 18339315 | D14: =(E14-C14)/C14*100 -> 0.24876611 | E14: 18384937 | F14: =(G14-E14)/E14*100 -> 0.05491996 | G14: 18395034 | H14: =(I14-G14)/G14*100 -> 0.1201683 | I14: 18417139 | J14: =(K14-I14)/I14*100 -> 0.46836808 | K14: 18503399 | L14: =(M14-K14)/K14*100 -> 0.49559003 | M14: 18595100
A16: Revenues
B17: Income from sales-type leases | C17: 512772 | D17: =(E17-C17)/C17*100 -> -0.094193911 | E17: 512289 | F17: =(G17-E17)/E17*100 -> 1.2496852 | G17: 518691 | H17: =(I17-G17)/G17*100 -> 1.1567581 | I17: =2068443-C17-E17-G17 -> 524691 | J17: =(K17-I17)/I17*100 -> 0.74577227 | K17: 528604 | L17: =(M17-K17)/K17*100 -> 0.32992562 | M17: 530348
B18: Income from lease financing receivables, loans and securities | C18: 409301 | D18: =(E18-C18)/C18*100 -> 1.0833103 | E18: 413735 | F18: =(G18-E18)/E18*100 -> 1.3003493 | G18: 419115 | H18: =(I18-G18)/G18*100 -> 0.38724455 | I18: =1662889-C18-E18-G18 -> 420738 | J18: =(K18-I18)/I18*100 -> 1.3647448 | K18: 426480 | L18: =(M18-K18)/K18*100 -> 3.2311011 | M18: 440260
B19: Other income | C19: 19312 | D19: =(E19-C19)/C19*100 -> 0.056959403 | E19: 19323 | F19: =(G19-E19)/E19*100 -> -0.041401439 | G19: 19315 | H19: =(I19-G19)/G19*100 -> 0.81283976 | I19: =77422-C19-E19-G19 -> 19472 | J19: =(K19-I19)/I19*100 -> 0.21055875 | K19: 19513 | L19: =(M19-K19)/K19*100 -> 0.11787014 | M19: 19536
B20: Golf revenues | C20: 10096 | D20: =(E20-C20)/C20*100 -> 15.451664 | E20: 11656 | F20: =(G20-E20)/E20*100 -> -35.243651 | G20: 7548 | H20: =(I20-G20)/G20*100 -> 47.734499 | I20: =40451-C20-E20-G20 -> 11151 | J20: =(K20-I20)/I20*100 -> -13.846292 | K20: 9607 | L20: =(M20-K20)/K20*100 -> 16.477568 | M20: 11190
A22: Operating Expenses
B23: General and administrative | C23: 16192 | D23: =(E23-C23)/C23*100 -> -2.6185771 | E23: 15768 | F23: =(G23-E23)/E23*100 -> 4.3759513 | G23: 16458 | H23: =(I23-G23)/G23*100 -> 25.720015 | I23: =69109-C23-E23-G23 -> 20691 | J23: =(K23-I23)/I23*100 -> -28.181335 | K23: 14860 | L23: =(M23-K23)/K23*100 -> -2.0121131 | M23: 14561
B24: Depreciation | C24: 1133 | D24: =(E24-C24)/C24*100 -> -12.444837 | E24: 992 | F24: =(G24-E24)/E24*100 -> 1.6129032 | G24: 1008 | H24: =(I24-G24)/G24*100 -> -1.5873016 | I24: =4125-C24-E24-G24 -> 992 | J24: =(K24-I24)/I24*100 -> 0.40322581 | K24: 996 | L24: =(M24-K24)/K24*100 -> -25.60241 | M24: 741
B25: Other expenses | C25: 19312 | D25: =(E25-C25)/C25*100 -> 0.056959403 | E25: 19323 | F25: =(G25-E25)/E25*100 -> -0.041401439 | G25: 19315 | H25: =(I25-G25)/G25*100 -> 0.81283976 | I25: =77422-C25-E25-G25 -> 19472 | J25: =(K25-I25)/I25*100 -> 0.21055875 | K25: 19513 | L25: =(M25-K25)/K25*100 -> 0.11787014 | M25: 19536
B26: Golf expenses | C26: 6511 | D26: =(E26-C26)/C26*100 -> 4.6383044 | E26: 6813 | F26: =(G26-E26)/E26*100 -> 0.16145604 | G26: 6824 | H26: =(I26-G26)/G26*100 -> -1.1283705 | I26: =26895-C26-E26-G26 -> 6747 | J26: =(K26-I26)/I26*100 -> -5.8544538 | K26: 6352 | L26: =(M26-K26)/K26*100 -> 4.2034005 | M26: 6619
B27: Change in allowance for credit losses (lost to uncollectable debt) | C27: 106918 | D27: =(E27-C27)/C27*100 -> -140.21774 | E27: -43000 | F27: =(G27-E27)/E27*100 -> -26.451163 | G27: -31626 | H27: =(I27-G27)/G27*100 -> -398.57712 | I27: =126720-C27-E27-G27 -> 94428 | J27: =(K27-I27)/I27*100 -> 97.988944 | K27: 186957 | L27: =(M27-K27)/K27*100 -> -175.95383 | M27: -142001
B28: Transaction and acquisition expenses | C28: 305 | D28: =(E28-C28)/C28*100 -> -15.081967 | E28: 259 | F28: =(G28-E28)/E28*100 -> 349.42085 | G28: 1164 | H28: =(I28-G28)/G28*100 -> 143.90034 | I28: =4567-C28-E28-G28 -> 2839 | J28: =(K28-I28)/I28*100 -> -98.414935 | K28: 45 | L28: =(M28-K28)/K28*100 -> 16420 | M28: 7434
A30: Cash Flows
B31: Net income | C31: 599803 | D31: =(E31-C31)/C31*100 -> 25.500039 | E31: =1352556-C31 -> 752753 | F31: =(G31-E31)/E31*100 -> -1.0988996 | G31: =2097037-E31-C31 -> 744481 | H31: =(I31-G31)/G31*100 -> -16.155684 | I31: =2721242-C31-E31-G31 -> 624205 | J31: =(K31-I31)/I31*100 -> -11.52506 | K31: 552265 | L31: =(M31-K31)/K31*100 -> 59.048283 | M31: =1430633-K31 -> 878368
B32: Net cash provided by operating activities | C32: 543739 | D32: =(E32-C32)/C32*100 -> 13.034011 | E32: =1158349-C32 -> 614610 | F32: =(G32-E32)/E32*100 -> -5.7854574 | G32: =1737401-E32-C32 -> 579052 | H32: =(I32-G32)/G32*100 -> 11.233015 | I32: =2381498-C32-E32-G32 -> 644097 | J32: =(K32-I32)/I32*100 -> -8.1102691 | K32: 591859 | L32: =(M32-K32)/K32*100 -> 8.1167981 | M32: =1231758-K32 -> 639899
B33: Net cash used in investing activities | C33: -109160 | D33: =(E33-C33)/C33*100 -> 185.70355 | E33: =-421034-C33 -> -311874 | F33: =(G33-E33)/E33*100 -> -22.541796 | G33: =-662606-C33-E33 -> -241572 | H33: =(I33-G33)/G33*100 -> 7.7008097 | I33: =-922781-C33-E33-G33 -> -260175 | J33: =(K33-I33)/I33*100 -> 48.200634 | K33: -385581 | L33: =(M33-K33)/K33*100 -> -14.476595 | M33: =-715343-K33 -> -329762
B34: Net cash used in financing activities | C34: -471781 | D34: =(E34-C34)/C34*100 -> -6.4915713 | E34: =-912936-C34 -> -441155 | F34: =(G34-E34)/E34*100 -> -25.357074 | G34: =-1242227-C34-E34 -> -329291 | H34: =(I34-G34)/G34*100 -> -34.740397 | I34: =-1457121-C34-E34-G34 -> -214894 | J34: =(K34-I34)/I34*100 -> 84.631493 | K34: -396762 | L34: =(M34-K34)/K34*100 -> 3.7523755 | M34: =-808412-K34 -> -411650
B35: Net decrease in cash, cash equivalents and restricted cash | C35: -37256 | D35: =(E35-C35)/C35*100 -> 270.83423 | E35: =-175414-C35 -> -138158 | F35: =(G35-E35)/E35*100 -> -106.15744 | G35: =-166907-C35-E35 -> 8507 | H35: =(I35-G35)/G35*100 -> 1885.988 | I35: =2041-C35-E35-G35 -> 168948 | J35: =(K35-I35)/I35*100 -> -212.63702 | K35: -190298 | L35: =(M35-K35)/K35*100 -> -46.749834 | M35: =-291632-K35 -> -101334
A37: DCF
B38: IBIT | C38: 601365 | E38: 755987 | G38: 746942 | I38: =2730946-C38-E38-G38 -> 626652 | K38: 549809 | M38: 883932
B39: Interest expense | C39: -204882 | E39: -205777 | G39: -207317 | I39: =-826097-C39-E39-G39 -> -208121 | K39: -209251 | M39: -213797
B40: Interest income | C40: 5293 | E40: 3926 | G40: 2797 | I40: =16095-C40-E40-G40 -> 4079 | K40: 3697 | M40: 2293
B41: EBIT | C41: =C38-C39-C40 -> 800954 | E41: =E38-E39-E40 -> 957838 | G41: =G38-G39-G40 -> 951462 | I41: =I38-I39-I40 -> 830694 | K41: =K38-K39-K40 -> 755363 | M41: =M38-M39-M40 -> 1095436
B43: Provision for income taxes | C43: -1562 | E43: -3234 | G43: -2461 | I43: =-9704-C43-E43-G43 -> -2447 | K43: 2456 | M43: -5564
B44: GAAP tax expense (not %) | C44: =-C43/C38 -> 0.0025974242 | E44: =-E43/E38 -> 0.0042778513 | G44: =-G43/G38 -> 0.0032947672 | I44: =-I43/I38 -> 0.0039048786 | K44: =-K43/K38 -> -0.0044670058 | M44: -0.004467
B45: NOPAT | C45: =C41*(1-C44) -> 798873.58 | E45: =E41*(1-E44) -> 953740.51 | G45: =G41*(1-G44) -> 948327.15 | I45: =I41*(1-I44) -> 827450.24 | K45: =K41*(1-K44) -> 758737.21 | M45: =M41*(1-M44) -> 1100329.3
B47: Add Back Non-Cash Charges (D&A) | C47: =C45+C24 -> 800006.58 | E47: =E45+E24 -> 954732.51 | G47: =G45+G24 -> 949335.15 | I47: =I45+I24 -> 828442.24 | K47: =K45+K24 -> 759733.21 | M47: =M45+M24 -> 1101070.3
...

Sheet DCF Calculations
B1: Quarter | C1: FCFF | D1: log(FCFF)
A2: 1 | B2: Q1 2024 | C2: ='Balance Sheet'!C57 -> 751536.58 | D2: =LOG(C2) -> 5.8759501 | F2: {=LINEST(D2:D7,A2:A7,TRUE,TRUE)} -> 0.013428692 | G2: 5.8998211
A3: 2 | B3: Q2 2024 | C3: ='Balance Sheet'!E57 -> 970576.51 | D3: =LOG(C3) -> 5.9870298 | F3: 0.017664418 | G3: 0.068793023
A4: 3 | B4: Q3 2024 | C4: ='Balance Sheet'!G57 -> 929858.15 | D4: =LOG(C4) -> 5.9684167 | F4: 0.126241 | G4: 0.073895561
A5: 4 | B5: Q4 2024 | C5: ='Balance Sheet'!I57 -> 861807.24 | D5: =LOG(C5) -> 5.9354101 | F5: 0.57792137 | G5: 4
A6: 5 | B6: Q1 2025 | C6: ='Balance Sheet'!K57 -> 730096.21 | D6: =LOG(C6) -> 5.8633801 | F6: 0.0031557708 | G6: 0.021842215
A7: 6 | B7: Q2 2025 | C7: ='Balance Sheet'!M57 -> 1123937.3 | D7: =LOG(C7) -> 6.0507421
F8: Quarterly g | G8: Annual g
B9: DCF models assume compounding (%), not linear increases, so we use the log-linear version. | F9: =EXP(F2)-1 -> 0.013519261 | G9: =F11 -> 0.055183585
F10: Annual g
F11: =POWER(1+F9,4)-1 -> 0.055183585
B13: Year (E) | C13: FCFF (LTM) | D13: FCFF (Norm) | F13: Q4 2025 (E) Norm | H13: FCFF LTM
B14: 2025 | C14: =H14 -> 3645698.9 | D14: =H17 -> 3858968.9 | F14: =AVERAGE(F17*(1+F9),C5*(1+F9)) -> 964154.73 | H14: =C7+C6+C5+C4 -> 3645698.9
B15: 2026 | C15: =(1+G9)*C14 -> 3846881.7 | D15: =(1+G9)*D14 -> 4071920.6
B16: 2027 | C16: =(1+G9)*C15 -> 4059166.4 | D16: =(1+G9)*D15 -> 4296623.8 | F16: Q3 2025 (E) Norm | H16: FCFF Norm
B17: 2028 | C17: =(1+G9)*C16 -> 4283165.7 | D17: =(1+G9)*D16 -> 4533726.9 | F17: =AVERAGE(C7*(1+F9),C4*(1+F9)) -> 1040780.6 | H17: =C7+C6+F17+F14 -> 3858968.9
B18: 2029 | C18: =(1+G9)*C17 -> 4519526.2 | D18: =(1+G9)*D17 -> 4783914.2
B19: 2030 | C19: =(1+G9)*C18 -> 4768929.8 | D19: =(1+G9)*D18 -> 5047907.8
B21: TV(Norm,2028,WACC=7.5%,base) | D21: =(C17*(1+0.025))/(0.075-0.025) -> 87804898
B22: TV(Norm,2028,WACC=7.5%,bullish) | D22: =(C17*(1+0.03))/(0.075-0.03) -> 98036905
B23: TV(Norm,2028,WACC=7.5%,bearish) | D23: =(C17*(1+0.015))/(0.075-0.015) -> 72456887
B25: TV(Norm,2028,WACC=8.5%,base) | D25: =(C17*(1+0.025))/(0.085-0.025) -> 73170748
B26: TV(Norm,2028,WACC=8.5%,bullish) | D26: =(C17*(1+0.03))/(0.085-0.03) -> 80212013
B27: TV(Norm,2028,WACC=8.5%,bearish) | D27: =(C17*(1+0.015))/(0.085-0.015) -> 62105903
B29: TV(Norm,2028,WACC=6.5%,base) | D29: =(C17*(1+0.025))/(0.065-0.025) -> 1.0975612e+08
B30: TV(Norm,2028,WACC=6.5%,bullish) | D30: =(C17*(1+0.03))/(0.065-0.03) -> 1.2604745e+08
B31: TV(Norm,2028,WACC=6.5%,bearish) | D31: =(C17*(1+0.015))/(0.065-0.015) -> 86948264

Sheet DCF Calculations (Continued)
A3: Index | B3: Year | C3: FCFF | D3: PV Factor (A) | E3: PV (A) | F3: PV Factor (B) | G3: PV(B) | H3: PV Factor (C) | I3: PV (C)
A4: 1 | B4: 2025 | C4: ='DCF Calculations'!C14 -> 3645698.9 | D4: =1/(POWER((1+C11),A4)) -> 0.93023256 | E4: =C4*D4 -> 3391347.8 | F4: =1/(POWER((1+C17),A4)) -> 0.92165899 | G4: =C4*F4 -> 3360091.2 | H4: =1/(POWER((1+C23),A4)) -> 0.92592593 | I4: =C4*H4 -> 3375647.1
A5: 2 | B5: 2026 | C5: ='DCF Calculations'!C15 -> 3846881.7 | D5: =1/(POWER((1+C11),A5)) -> 0.86533261 | E5: =C5*D5 -> 3328832.2 | F5: =1/(POWER((1+C17),A5)) -> 0.84945529 | G5: =C5*F5 -> 3267754 | H5: =1/(POWER((1+C23),A5)) -> 0.85733882 | I5: =C5*H5 -> 3298081
A6: 3 | B6: 2027 | C6: ='DCF Calculations'!C16 -> 4059166.4 | D6: =1/(POWER((1+C11),A6)) -> 0.80496057 | E6: =C6*D6 -> 3267468.9 | F6: =1/(POWER((1+C17),A6)) -> 0.7829081 | G6: =C6*F6 -> 3177954.2 | H6: =1/(POWER((1+C23),A6)) -> 0.79383224 | I6: =C6*H6 -> 3222297.1
A7: 4 | B7: 2028 | C7: ='DCF Calculations'!C17 -> 4283165.7 | D7: =1/(POWER((1+C11),A7)) -> 0.74880053 | E7: =C7*D7 -> 3207236.8 | F7: =1/(POWER((1+C17),A7)) -> 0.72157428 | G7: =C7*F7 -> 3090622.2 | H7: =1/(POWER((1+C23),A7)) -> 0.73502985 | I7: =C7*H7 -> 3148254.7
B10: Gterm (A) | C10: 0.03 | E10: Net Debt | F10: ='Balance Sheet'!M10 -> 16922273
B11: WACC A | C11: 0.075 | E11: Shares | F11: 1066369778
B12: Terminal | C12: =('DCF Calculations'!C17*(1+C10)/(C11-C10)) -> 98036905
B13: PV(Terminal) | C13: =D7*C12 -> 73410086
B14: EV (A) | C14: =SUM(E4:E7,C13) -> 86604972 | E14: Equity Value | F14: =C14-F10 -> 69682699 | H14: Value/share | I14: =F14*1000/F11 -> 65.345718
B16: Gterm (B) | C16: 0.03
B17: WACC B | C17: 0.085
B18: Terminal | C18: =('DCF Calculations'!C17*(1+C16)/(C17-C16)) -> 80212013
B19: PV(Terminal) | C19: =F7*C18 -> 57878926
B20: EV (B) | C20: =SUM(G4:G7,C19) -> 70775347 | E20: Equity Value | F20: =C20-F10 -> 53853074 | H20: Value/share | I20: =F20*1000/F11 -> 50.501313
B22: Gterm (C) | C22: 0.025
B23: WACC C | C23: 0.08
B24: Terminal | C24: =('DCF Calculations'!C17*(1+C22)/(C23-C22)) -> 79822634
B25: PV(Terminal) | C25: =H7*C24 -> 58672019
B26: EV (C) | C26: =SUM(H4:H7,C25) -> 58672022 | E26: Equity Value | F26: =C26-F10 -> 41749749 | H26: Value/share | I26: =F26*1000/F11 -> 39.151287
